{
 "cells": [
  {
   "cell_type": "code",
   "execution_count": 1,
   "metadata": {},
   "outputs": [],
   "source": [
    "from transformers import AutoTokenizer, AutoModel"
   ]
  },
  {
   "cell_type": "code",
   "execution_count": 3,
   "metadata": {},
   "outputs": [
    {
     "ename": "OSError",
     "evalue": "We couldn't connect to 'https://huggingface.co' to load this file, couldn't find it in the cached files and it looks like bert-base-uncased is not the path to a directory containing a file named config.json.\nCheckout your internet connection or see how to run the library in offline mode at 'https://huggingface.co/docs/transformers/installation#offline-mode'.",
     "output_type": "error",
     "traceback": [
      "\u001b[0;31m---------------------------------------------------------------------------\u001b[0m",
      "\u001b[0;31mLocalEntryNotFoundError\u001b[0m                   Traceback (most recent call last)",
      "File \u001b[0;32m/ai/anaconda3/envs/bst/lib/python3.8/site-packages/transformers/utils/hub.py:409\u001b[0m, in \u001b[0;36mcached_file\u001b[0;34m(path_or_repo_id, filename, cache_dir, force_download, resume_download, proxies, use_auth_token, revision, local_files_only, subfolder, user_agent, _raise_exceptions_for_missing_entries, _raise_exceptions_for_connection_errors, _commit_hash)\u001b[0m\n\u001b[1;32m    407\u001b[0m \u001b[38;5;28;01mtry\u001b[39;00m:\n\u001b[1;32m    408\u001b[0m     \u001b[38;5;66;03m# Load from URL or cache if already cached\u001b[39;00m\n\u001b[0;32m--> 409\u001b[0m     resolved_file \u001b[38;5;241m=\u001b[39m \u001b[43mhf_hub_download\u001b[49m\u001b[43m(\u001b[49m\n\u001b[1;32m    410\u001b[0m \u001b[43m        \u001b[49m\u001b[43mpath_or_repo_id\u001b[49m\u001b[43m,\u001b[49m\n\u001b[1;32m    411\u001b[0m \u001b[43m        \u001b[49m\u001b[43mfilename\u001b[49m\u001b[43m,\u001b[49m\n\u001b[1;32m    412\u001b[0m \u001b[43m        \u001b[49m\u001b[43msubfolder\u001b[49m\u001b[38;5;241;43m=\u001b[39;49m\u001b[38;5;28;43;01mNone\u001b[39;49;00m\u001b[43m \u001b[49m\u001b[38;5;28;43;01mif\u001b[39;49;00m\u001b[43m \u001b[49m\u001b[38;5;28;43mlen\u001b[39;49m\u001b[43m(\u001b[49m\u001b[43msubfolder\u001b[49m\u001b[43m)\u001b[49m\u001b[43m \u001b[49m\u001b[38;5;241;43m==\u001b[39;49m\u001b[43m \u001b[49m\u001b[38;5;241;43m0\u001b[39;49m\u001b[43m \u001b[49m\u001b[38;5;28;43;01melse\u001b[39;49;00m\u001b[43m \u001b[49m\u001b[43msubfolder\u001b[49m\u001b[43m,\u001b[49m\n\u001b[1;32m    413\u001b[0m \u001b[43m        \u001b[49m\u001b[43mrevision\u001b[49m\u001b[38;5;241;43m=\u001b[39;49m\u001b[43mrevision\u001b[49m\u001b[43m,\u001b[49m\n\u001b[1;32m    414\u001b[0m \u001b[43m        \u001b[49m\u001b[43mcache_dir\u001b[49m\u001b[38;5;241;43m=\u001b[39;49m\u001b[43mcache_dir\u001b[49m\u001b[43m,\u001b[49m\n\u001b[1;32m    415\u001b[0m \u001b[43m        \u001b[49m\u001b[43muser_agent\u001b[49m\u001b[38;5;241;43m=\u001b[39;49m\u001b[43muser_agent\u001b[49m\u001b[43m,\u001b[49m\n\u001b[1;32m    416\u001b[0m \u001b[43m        \u001b[49m\u001b[43mforce_download\u001b[49m\u001b[38;5;241;43m=\u001b[39;49m\u001b[43mforce_download\u001b[49m\u001b[43m,\u001b[49m\n\u001b[1;32m    417\u001b[0m \u001b[43m        \u001b[49m\u001b[43mproxies\u001b[49m\u001b[38;5;241;43m=\u001b[39;49m\u001b[43mproxies\u001b[49m\u001b[43m,\u001b[49m\n\u001b[1;32m    418\u001b[0m \u001b[43m        \u001b[49m\u001b[43mresume_download\u001b[49m\u001b[38;5;241;43m=\u001b[39;49m\u001b[43mresume_download\u001b[49m\u001b[43m,\u001b[49m\n\u001b[1;32m    419\u001b[0m \u001b[43m        \u001b[49m\u001b[43muse_auth_token\u001b[49m\u001b[38;5;241;43m=\u001b[39;49m\u001b[43muse_auth_token\u001b[49m\u001b[43m,\u001b[49m\n\u001b[1;32m    420\u001b[0m \u001b[43m        \u001b[49m\u001b[43mlocal_files_only\u001b[49m\u001b[38;5;241;43m=\u001b[39;49m\u001b[43mlocal_files_only\u001b[49m\u001b[43m,\u001b[49m\n\u001b[1;32m    421\u001b[0m \u001b[43m    \u001b[49m\u001b[43m)\u001b[49m\n\u001b[1;32m    423\u001b[0m \u001b[38;5;28;01mexcept\u001b[39;00m RepositoryNotFoundError:\n",
      "File \u001b[0;32m/ai/anaconda3/envs/bst/lib/python3.8/site-packages/huggingface_hub/utils/_validators.py:120\u001b[0m, in \u001b[0;36mvalidate_hf_hub_args.<locals>._inner_fn\u001b[0;34m(*args, **kwargs)\u001b[0m\n\u001b[1;32m    118\u001b[0m     kwargs \u001b[38;5;241m=\u001b[39m smoothly_deprecate_use_auth_token(fn_name\u001b[38;5;241m=\u001b[39mfn\u001b[38;5;241m.\u001b[39m\u001b[38;5;18m__name__\u001b[39m, has_token\u001b[38;5;241m=\u001b[39mhas_token, kwargs\u001b[38;5;241m=\u001b[39mkwargs)\n\u001b[0;32m--> 120\u001b[0m \u001b[38;5;28;01mreturn\u001b[39;00m \u001b[43mfn\u001b[49m\u001b[43m(\u001b[49m\u001b[38;5;241;43m*\u001b[39;49m\u001b[43margs\u001b[49m\u001b[43m,\u001b[49m\u001b[43m \u001b[49m\u001b[38;5;241;43m*\u001b[39;49m\u001b[38;5;241;43m*\u001b[39;49m\u001b[43mkwargs\u001b[49m\u001b[43m)\u001b[49m\n",
      "File \u001b[0;32m/ai/anaconda3/envs/bst/lib/python3.8/site-packages/huggingface_hub/file_download.py:1227\u001b[0m, in \u001b[0;36mhf_hub_download\u001b[0;34m(repo_id, filename, subfolder, repo_type, revision, library_name, library_version, cache_dir, local_dir, local_dir_use_symlinks, user_agent, force_download, force_filename, proxies, etag_timeout, resume_download, token, local_files_only, legacy_cache_layout)\u001b[0m\n\u001b[1;32m   1226\u001b[0m     \u001b[38;5;28;01melse\u001b[39;00m:\n\u001b[0;32m-> 1227\u001b[0m         \u001b[38;5;28;01mraise\u001b[39;00m LocalEntryNotFoundError(\n\u001b[1;32m   1228\u001b[0m             \u001b[38;5;124m\"\u001b[39m\u001b[38;5;124mConnection error, and we cannot find the requested files in\u001b[39m\u001b[38;5;124m\"\u001b[39m\n\u001b[1;32m   1229\u001b[0m             \u001b[38;5;124m\"\u001b[39m\u001b[38;5;124m the disk cache. Please try again or make sure your Internet\u001b[39m\u001b[38;5;124m\"\u001b[39m\n\u001b[1;32m   1230\u001b[0m             \u001b[38;5;124m\"\u001b[39m\u001b[38;5;124m connection is on.\u001b[39m\u001b[38;5;124m\"\u001b[39m\n\u001b[1;32m   1231\u001b[0m         )\n\u001b[1;32m   1233\u001b[0m \u001b[38;5;66;03m# From now on, etag and commit_hash are not None.\u001b[39;00m\n",
      "\u001b[0;31mLocalEntryNotFoundError\u001b[0m: Connection error, and we cannot find the requested files in the disk cache. Please try again or make sure your Internet connection is on.",
      "\nDuring handling of the above exception, another exception occurred:\n",
      "\u001b[0;31mOSError\u001b[0m                                   Traceback (most recent call last)",
      "Cell \u001b[0;32mIn[3], line 1\u001b[0m\n\u001b[0;32m----> 1\u001b[0m model \u001b[38;5;241m=\u001b[39m \u001b[43mAutoModel\u001b[49m\u001b[38;5;241;43m.\u001b[39;49m\u001b[43mfrom_pretrained\u001b[49m\u001b[43m(\u001b[49m\u001b[38;5;124;43m'\u001b[39;49m\u001b[38;5;124;43mbert-base-uncased\u001b[39;49m\u001b[38;5;124;43m'\u001b[39;49m\u001b[43m,\u001b[49m\u001b[43m \u001b[49m\u001b[43mmirror\u001b[49m\u001b[38;5;241;43m=\u001b[39;49m\u001b[38;5;124;43m'\u001b[39;49m\u001b[38;5;124;43mbfsu\u001b[39;49m\u001b[38;5;124;43m'\u001b[39;49m\u001b[43m)\u001b[49m\n",
      "File \u001b[0;32m/ai/anaconda3/envs/bst/lib/python3.8/site-packages/transformers/models/auto/auto_factory.py:441\u001b[0m, in \u001b[0;36m_BaseAutoModelClass.from_pretrained\u001b[0;34m(cls, pretrained_model_name_or_path, *model_args, **kwargs)\u001b[0m\n\u001b[1;32m    438\u001b[0m     \u001b[38;5;28;01mif\u001b[39;00m kwargs_copy\u001b[38;5;241m.\u001b[39mget(\u001b[38;5;124m\"\u001b[39m\u001b[38;5;124mtorch_dtype\u001b[39m\u001b[38;5;124m\"\u001b[39m, \u001b[38;5;28;01mNone\u001b[39;00m) \u001b[38;5;241m==\u001b[39m \u001b[38;5;124m\"\u001b[39m\u001b[38;5;124mauto\u001b[39m\u001b[38;5;124m\"\u001b[39m:\n\u001b[1;32m    439\u001b[0m         _ \u001b[38;5;241m=\u001b[39m kwargs_copy\u001b[38;5;241m.\u001b[39mpop(\u001b[38;5;124m\"\u001b[39m\u001b[38;5;124mtorch_dtype\u001b[39m\u001b[38;5;124m\"\u001b[39m)\n\u001b[0;32m--> 441\u001b[0m     config, kwargs \u001b[38;5;241m=\u001b[39m \u001b[43mAutoConfig\u001b[49m\u001b[38;5;241;43m.\u001b[39;49m\u001b[43mfrom_pretrained\u001b[49m\u001b[43m(\u001b[49m\n\u001b[1;32m    442\u001b[0m \u001b[43m        \u001b[49m\u001b[43mpretrained_model_name_or_path\u001b[49m\u001b[43m,\u001b[49m\n\u001b[1;32m    443\u001b[0m \u001b[43m        \u001b[49m\u001b[43mreturn_unused_kwargs\u001b[49m\u001b[38;5;241;43m=\u001b[39;49m\u001b[38;5;28;43;01mTrue\u001b[39;49;00m\u001b[43m,\u001b[49m\n\u001b[1;32m    444\u001b[0m \u001b[43m        \u001b[49m\u001b[43mtrust_remote_code\u001b[49m\u001b[38;5;241;43m=\u001b[39;49m\u001b[43mtrust_remote_code\u001b[49m\u001b[43m,\u001b[49m\n\u001b[1;32m    445\u001b[0m \u001b[43m        \u001b[49m\u001b[38;5;241;43m*\u001b[39;49m\u001b[38;5;241;43m*\u001b[39;49m\u001b[43mhub_kwargs\u001b[49m\u001b[43m,\u001b[49m\n\u001b[1;32m    446\u001b[0m \u001b[43m        \u001b[49m\u001b[38;5;241;43m*\u001b[39;49m\u001b[38;5;241;43m*\u001b[39;49m\u001b[43mkwargs_copy\u001b[49m\u001b[43m,\u001b[49m\n\u001b[1;32m    447\u001b[0m \u001b[43m    \u001b[49m\u001b[43m)\u001b[49m\n\u001b[1;32m    448\u001b[0m \u001b[38;5;28;01mif\u001b[39;00m \u001b[38;5;28mhasattr\u001b[39m(config, \u001b[38;5;124m\"\u001b[39m\u001b[38;5;124mauto_map\u001b[39m\u001b[38;5;124m\"\u001b[39m) \u001b[38;5;129;01mand\u001b[39;00m \u001b[38;5;28mcls\u001b[39m\u001b[38;5;241m.\u001b[39m\u001b[38;5;18m__name__\u001b[39m \u001b[38;5;129;01min\u001b[39;00m config\u001b[38;5;241m.\u001b[39mauto_map:\n\u001b[1;32m    449\u001b[0m     \u001b[38;5;28;01mif\u001b[39;00m \u001b[38;5;129;01mnot\u001b[39;00m trust_remote_code:\n",
      "File \u001b[0;32m/ai/anaconda3/envs/bst/lib/python3.8/site-packages/transformers/models/auto/configuration_auto.py:896\u001b[0m, in \u001b[0;36mAutoConfig.from_pretrained\u001b[0;34m(cls, pretrained_model_name_or_path, **kwargs)\u001b[0m\n\u001b[1;32m    894\u001b[0m kwargs[\u001b[38;5;124m\"\u001b[39m\u001b[38;5;124mname_or_path\u001b[39m\u001b[38;5;124m\"\u001b[39m] \u001b[38;5;241m=\u001b[39m pretrained_model_name_or_path\n\u001b[1;32m    895\u001b[0m trust_remote_code \u001b[38;5;241m=\u001b[39m kwargs\u001b[38;5;241m.\u001b[39mpop(\u001b[38;5;124m\"\u001b[39m\u001b[38;5;124mtrust_remote_code\u001b[39m\u001b[38;5;124m\"\u001b[39m, \u001b[38;5;28;01mFalse\u001b[39;00m)\n\u001b[0;32m--> 896\u001b[0m config_dict, unused_kwargs \u001b[38;5;241m=\u001b[39m \u001b[43mPretrainedConfig\u001b[49m\u001b[38;5;241;43m.\u001b[39;49m\u001b[43mget_config_dict\u001b[49m\u001b[43m(\u001b[49m\u001b[43mpretrained_model_name_or_path\u001b[49m\u001b[43m,\u001b[49m\u001b[43m \u001b[49m\u001b[38;5;241;43m*\u001b[39;49m\u001b[38;5;241;43m*\u001b[39;49m\u001b[43mkwargs\u001b[49m\u001b[43m)\u001b[49m\n\u001b[1;32m    897\u001b[0m \u001b[38;5;28;01mif\u001b[39;00m \u001b[38;5;124m\"\u001b[39m\u001b[38;5;124mauto_map\u001b[39m\u001b[38;5;124m\"\u001b[39m \u001b[38;5;129;01min\u001b[39;00m config_dict \u001b[38;5;129;01mand\u001b[39;00m \u001b[38;5;124m\"\u001b[39m\u001b[38;5;124mAutoConfig\u001b[39m\u001b[38;5;124m\"\u001b[39m \u001b[38;5;129;01min\u001b[39;00m config_dict[\u001b[38;5;124m\"\u001b[39m\u001b[38;5;124mauto_map\u001b[39m\u001b[38;5;124m\"\u001b[39m]:\n\u001b[1;32m    898\u001b[0m     \u001b[38;5;28;01mif\u001b[39;00m \u001b[38;5;129;01mnot\u001b[39;00m trust_remote_code:\n",
      "File \u001b[0;32m/ai/anaconda3/envs/bst/lib/python3.8/site-packages/transformers/configuration_utils.py:573\u001b[0m, in \u001b[0;36mPretrainedConfig.get_config_dict\u001b[0;34m(cls, pretrained_model_name_or_path, **kwargs)\u001b[0m\n\u001b[1;32m    571\u001b[0m original_kwargs \u001b[38;5;241m=\u001b[39m copy\u001b[38;5;241m.\u001b[39mdeepcopy(kwargs)\n\u001b[1;32m    572\u001b[0m \u001b[38;5;66;03m# Get config dict associated with the base config file\u001b[39;00m\n\u001b[0;32m--> 573\u001b[0m config_dict, kwargs \u001b[38;5;241m=\u001b[39m \u001b[38;5;28;43mcls\u001b[39;49m\u001b[38;5;241;43m.\u001b[39;49m\u001b[43m_get_config_dict\u001b[49m\u001b[43m(\u001b[49m\u001b[43mpretrained_model_name_or_path\u001b[49m\u001b[43m,\u001b[49m\u001b[43m \u001b[49m\u001b[38;5;241;43m*\u001b[39;49m\u001b[38;5;241;43m*\u001b[39;49m\u001b[43mkwargs\u001b[49m\u001b[43m)\u001b[49m\n\u001b[1;32m    574\u001b[0m \u001b[38;5;28;01mif\u001b[39;00m \u001b[38;5;124m\"\u001b[39m\u001b[38;5;124m_commit_hash\u001b[39m\u001b[38;5;124m\"\u001b[39m \u001b[38;5;129;01min\u001b[39;00m config_dict:\n\u001b[1;32m    575\u001b[0m     original_kwargs[\u001b[38;5;124m\"\u001b[39m\u001b[38;5;124m_commit_hash\u001b[39m\u001b[38;5;124m\"\u001b[39m] \u001b[38;5;241m=\u001b[39m config_dict[\u001b[38;5;124m\"\u001b[39m\u001b[38;5;124m_commit_hash\u001b[39m\u001b[38;5;124m\"\u001b[39m]\n",
      "File \u001b[0;32m/ai/anaconda3/envs/bst/lib/python3.8/site-packages/transformers/configuration_utils.py:628\u001b[0m, in \u001b[0;36mPretrainedConfig._get_config_dict\u001b[0;34m(cls, pretrained_model_name_or_path, **kwargs)\u001b[0m\n\u001b[1;32m    624\u001b[0m configuration_file \u001b[38;5;241m=\u001b[39m kwargs\u001b[38;5;241m.\u001b[39mpop(\u001b[38;5;124m\"\u001b[39m\u001b[38;5;124m_configuration_file\u001b[39m\u001b[38;5;124m\"\u001b[39m, CONFIG_NAME)\n\u001b[1;32m    626\u001b[0m \u001b[38;5;28;01mtry\u001b[39;00m:\n\u001b[1;32m    627\u001b[0m     \u001b[38;5;66;03m# Load from local folder or from cache or download from model Hub and cache\u001b[39;00m\n\u001b[0;32m--> 628\u001b[0m     resolved_config_file \u001b[38;5;241m=\u001b[39m \u001b[43mcached_file\u001b[49m\u001b[43m(\u001b[49m\n\u001b[1;32m    629\u001b[0m \u001b[43m        \u001b[49m\u001b[43mpretrained_model_name_or_path\u001b[49m\u001b[43m,\u001b[49m\n\u001b[1;32m    630\u001b[0m \u001b[43m        \u001b[49m\u001b[43mconfiguration_file\u001b[49m\u001b[43m,\u001b[49m\n\u001b[1;32m    631\u001b[0m \u001b[43m        \u001b[49m\u001b[43mcache_dir\u001b[49m\u001b[38;5;241;43m=\u001b[39;49m\u001b[43mcache_dir\u001b[49m\u001b[43m,\u001b[49m\n\u001b[1;32m    632\u001b[0m \u001b[43m        \u001b[49m\u001b[43mforce_download\u001b[49m\u001b[38;5;241;43m=\u001b[39;49m\u001b[43mforce_download\u001b[49m\u001b[43m,\u001b[49m\n\u001b[1;32m    633\u001b[0m \u001b[43m        \u001b[49m\u001b[43mproxies\u001b[49m\u001b[38;5;241;43m=\u001b[39;49m\u001b[43mproxies\u001b[49m\u001b[43m,\u001b[49m\n\u001b[1;32m    634\u001b[0m \u001b[43m        \u001b[49m\u001b[43mresume_download\u001b[49m\u001b[38;5;241;43m=\u001b[39;49m\u001b[43mresume_download\u001b[49m\u001b[43m,\u001b[49m\n\u001b[1;32m    635\u001b[0m \u001b[43m        \u001b[49m\u001b[43mlocal_files_only\u001b[49m\u001b[38;5;241;43m=\u001b[39;49m\u001b[43mlocal_files_only\u001b[49m\u001b[43m,\u001b[49m\n\u001b[1;32m    636\u001b[0m \u001b[43m        \u001b[49m\u001b[43muse_auth_token\u001b[49m\u001b[38;5;241;43m=\u001b[39;49m\u001b[43muse_auth_token\u001b[49m\u001b[43m,\u001b[49m\n\u001b[1;32m    637\u001b[0m \u001b[43m        \u001b[49m\u001b[43muser_agent\u001b[49m\u001b[38;5;241;43m=\u001b[39;49m\u001b[43muser_agent\u001b[49m\u001b[43m,\u001b[49m\n\u001b[1;32m    638\u001b[0m \u001b[43m        \u001b[49m\u001b[43mrevision\u001b[49m\u001b[38;5;241;43m=\u001b[39;49m\u001b[43mrevision\u001b[49m\u001b[43m,\u001b[49m\n\u001b[1;32m    639\u001b[0m \u001b[43m        \u001b[49m\u001b[43msubfolder\u001b[49m\u001b[38;5;241;43m=\u001b[39;49m\u001b[43msubfolder\u001b[49m\u001b[43m,\u001b[49m\n\u001b[1;32m    640\u001b[0m \u001b[43m        \u001b[49m\u001b[43m_commit_hash\u001b[49m\u001b[38;5;241;43m=\u001b[39;49m\u001b[43mcommit_hash\u001b[49m\u001b[43m,\u001b[49m\n\u001b[1;32m    641\u001b[0m \u001b[43m    \u001b[49m\u001b[43m)\u001b[49m\n\u001b[1;32m    642\u001b[0m     commit_hash \u001b[38;5;241m=\u001b[39m extract_commit_hash(resolved_config_file, commit_hash)\n\u001b[1;32m    643\u001b[0m \u001b[38;5;28;01mexcept\u001b[39;00m \u001b[38;5;167;01mEnvironmentError\u001b[39;00m:\n\u001b[1;32m    644\u001b[0m     \u001b[38;5;66;03m# Raise any environment error raise by `cached_file`. It will have a helpful error message adapted to\u001b[39;00m\n\u001b[1;32m    645\u001b[0m     \u001b[38;5;66;03m# the original exception.\u001b[39;00m\n",
      "File \u001b[0;32m/ai/anaconda3/envs/bst/lib/python3.8/site-packages/transformers/utils/hub.py:443\u001b[0m, in \u001b[0;36mcached_file\u001b[0;34m(path_or_repo_id, filename, cache_dir, force_download, resume_download, proxies, use_auth_token, revision, local_files_only, subfolder, user_agent, _raise_exceptions_for_missing_entries, _raise_exceptions_for_connection_errors, _commit_hash)\u001b[0m\n\u001b[1;32m    441\u001b[0m     \u001b[38;5;28;01mif\u001b[39;00m \u001b[38;5;129;01mnot\u001b[39;00m _raise_exceptions_for_missing_entries \u001b[38;5;129;01mor\u001b[39;00m \u001b[38;5;129;01mnot\u001b[39;00m _raise_exceptions_for_connection_errors:\n\u001b[1;32m    442\u001b[0m         \u001b[38;5;28;01mreturn\u001b[39;00m \u001b[38;5;28;01mNone\u001b[39;00m\n\u001b[0;32m--> 443\u001b[0m     \u001b[38;5;28;01mraise\u001b[39;00m \u001b[38;5;167;01mEnvironmentError\u001b[39;00m(\n\u001b[1;32m    444\u001b[0m         \u001b[38;5;124mf\u001b[39m\u001b[38;5;124m\"\u001b[39m\u001b[38;5;124mWe couldn\u001b[39m\u001b[38;5;124m'\u001b[39m\u001b[38;5;124mt connect to \u001b[39m\u001b[38;5;124m'\u001b[39m\u001b[38;5;132;01m{\u001b[39;00mHUGGINGFACE_CO_RESOLVE_ENDPOINT\u001b[38;5;132;01m}\u001b[39;00m\u001b[38;5;124m'\u001b[39m\u001b[38;5;124m to load this file, couldn\u001b[39m\u001b[38;5;124m'\u001b[39m\u001b[38;5;124mt find it in the\u001b[39m\u001b[38;5;124m\"\u001b[39m\n\u001b[1;32m    445\u001b[0m         \u001b[38;5;124mf\u001b[39m\u001b[38;5;124m\"\u001b[39m\u001b[38;5;124m cached files and it looks like \u001b[39m\u001b[38;5;132;01m{\u001b[39;00mpath_or_repo_id\u001b[38;5;132;01m}\u001b[39;00m\u001b[38;5;124m is not the path to a directory containing a file named\u001b[39m\u001b[38;5;124m\"\u001b[39m\n\u001b[1;32m    446\u001b[0m         \u001b[38;5;124mf\u001b[39m\u001b[38;5;124m\"\u001b[39m\u001b[38;5;124m \u001b[39m\u001b[38;5;132;01m{\u001b[39;00mfull_filename\u001b[38;5;132;01m}\u001b[39;00m\u001b[38;5;124m.\u001b[39m\u001b[38;5;130;01m\\n\u001b[39;00m\u001b[38;5;124mCheckout your internet connection or see how to run the library in offline mode at\u001b[39m\u001b[38;5;124m\"\u001b[39m\n\u001b[1;32m    447\u001b[0m         \u001b[38;5;124m\"\u001b[39m\u001b[38;5;124m \u001b[39m\u001b[38;5;124m'\u001b[39m\u001b[38;5;124mhttps://huggingface.co/docs/transformers/installation#offline-mode\u001b[39m\u001b[38;5;124m'\u001b[39m\u001b[38;5;124m.\u001b[39m\u001b[38;5;124m\"\u001b[39m\n\u001b[1;32m    448\u001b[0m     )\n\u001b[1;32m    449\u001b[0m \u001b[38;5;28;01mexcept\u001b[39;00m EntryNotFoundError:\n\u001b[1;32m    450\u001b[0m     \u001b[38;5;28;01mif\u001b[39;00m \u001b[38;5;129;01mnot\u001b[39;00m _raise_exceptions_for_missing_entries:\n",
      "\u001b[0;31mOSError\u001b[0m: We couldn't connect to 'https://huggingface.co' to load this file, couldn't find it in the cached files and it looks like bert-base-uncased is not the path to a directory containing a file named config.json.\nCheckout your internet connection or see how to run the library in offline mode at 'https://huggingface.co/docs/transformers/installation#offline-mode'."
     ]
    }
   ],
   "source": []
  },
  {
   "cell_type": "code",
   "execution_count": null,
   "metadata": {},
   "outputs": [],
   "source": []
  }
 ],
 "metadata": {
  "kernelspec": {
   "display_name": "bst",
   "language": "python",
   "name": "python3"
  },
  "language_info": {
   "codemirror_mode": {
    "name": "ipython",
    "version": 3
   },
   "file_extension": ".py",
   "mimetype": "text/x-python",
   "name": "python",
   "nbconvert_exporter": "python",
   "pygments_lexer": "ipython3",
   "version": "3.8.8"
  }
 },
 "nbformat": 4,
 "nbformat_minor": 2
}
